INFO 2025-08-06 07:48:08,800 autoreload 9432 9392 Watching for file changes with StatReloader
INFO 2025-08-06 07:48:47,196 error_handling 9432 2944 Starting operation: product_detail
INFO 2025-08-06 07:48:47,200 error_handling 9432 2944 Operation completed: product_detail in 0.00s
WARNING 2025-08-06 07:51:13,367 log 9432 2944 Not Found: /cart/count/
WARNING 2025-08-06 07:51:21,203 log 9432 2944 Not Found: /cart/count/
WARNING 2025-08-06 09:02:12,807 log 9432 4608 Not Found: /cart/count/
WARNING 2025-08-06 09:02:28,069 log 9432 4608 Not Found: /cart/count/
INFO 2025-08-06 09:30:11,899 autoreload 7944 12812 Watching for file changes with StatReloader
WARNING 2025-08-06 09:30:29,585 log 7944 6588 Not Found: /cart/count/
WARNING 2025-08-06 09:30:37,615 log 7944 6588 Not Found: /cart/count/
WARNING 2025-08-06 09:34:09,373 log 7944 14168 Not Found: /cart/count/
WARNING 2025-08-06 09:38:37,696 log 7944 14168 Not Found: /.well-known/appspecific/com.chrome.devtools.json
WARNING 2025-08-06 09:38:51,258 log 7944 14168 Not Found: /.well-known/appspecific/com.chrome.devtools.json
WARNING 2025-08-06 09:38:51,588 log 7944 14168 Not Found: /cart/count/
WARNING 2025-08-06 09:38:58,005 log 7944 14168 Not Found: /.well-known/appspecific/com.chrome.devtools.json
INFO 2025-08-06 11:47:44,856 autoreload 2944 14000 Watching for file changes with StatReloader
INFO 2025-08-06 11:53:08,187 error_handling 2944 6300 Starting operation: product_detail
INFO 2025-08-06 11:53:08,190 error_handling 2944 6300 Operation completed: product_detail in 0.00s
WARNING 2025-08-06 11:53:25,450 log 2944 6300 Not Found: /cart/count/
WARNING 2025-08-06 11:53:44,665 log 2944 6300 Not Found: /cart/count/
WARNING 2025-08-06 11:53:53,847 log 2944 6300 Not Found: /cart/count/
WARNING 2025-08-06 11:54:03,732 log 2944 6300 Forbidden (CSRF token from the 'X-Csrftoken' HTTP header has incorrect length.): /shop/notifications/3/read/
WARNING 2025-08-06 11:54:13,509 log 2944 6300 Not Found: /cart/count/
WARNING 2025-08-06 11:54:37,247 log 2944 6300 Not Found: /cart/count/
WARNING 2025-08-06 11:57:27,160 log 2944 6300 Not Found: /cart/count/
WARNING 2025-08-06 11:59:15,457 log 2944 6300 Not Found: /cart/count/
WARNING 2025-08-06 12:19:41,062 log 2944 1116 Not Found: /cart/count/
WARNING 2025-08-06 12:20:02,304 log 2944 1116 Not Found: /cart/count/
INFO 2025-08-06 12:36:41,267 autoreload 13740 5452 Watching for file changes with StatReloader
WARNING 2025-08-06 12:36:57,303 log 13740 14132 Not Found: /cart/count/
INFO 2025-08-06 12:37:05,721 error_handling 13740 14132 Starting operation: product_detail
INFO 2025-08-06 12:37:05,722 error_handling 13740 14132 Operation completed: product_detail in 0.00s
INFO 2025-08-06 12:52:53,183 autoreload 13824 2832 Watching for file changes with StatReloader
ERROR 2025-08-06 12:53:05,952 log 13824 10364 Internal Server Error: /shop/cart/count/
Traceback (most recent call last):
  File "C:\Users\Mobile Gandom\AppData\Local\Programs\Python\Python312\Lib\site-packages\django\db\backends\utils.py", line 105, in _execute
    return self.cursor.execute(sql, params)
           ^^^^^^^^^^^^^^^^^^^^^^^^^^^^^^^^
  File "C:\Users\Mobile Gandom\AppData\Local\Programs\Python\Python312\Lib\site-packages\django\db\backends\sqlite3\base.py", line 354, in execute
    return super().execute(query, params)
           ^^^^^^^^^^^^^^^^^^^^^^^^^^^^^^
sqlite3.OperationalError: no such column: shop_cartitem.grind_type

The above exception was the direct cause of the following exception:

Traceback (most recent call last):
  File "C:\Users\Mobile Gandom\AppData\Local\Programs\Python\Python312\Lib\site-packages\django\core\handlers\exception.py", line 55, in inner
    response = get_response(request)
               ^^^^^^^^^^^^^^^^^^^^^
  File "C:\Users\Mobile Gandom\AppData\Local\Programs\Python\Python312\Lib\site-packages\django\core\handlers\base.py", line 197, in _get_response
    response = wrapped_callback(request, *callback_args, **callback_kwargs)
               ^^^^^^^^^^^^^^^^^^^^^^^^^^^^^^^^^^^^^^^^^^^^^^^^^^^^^^^^^^^^
  File "C:\Users\Mobile Gandom\AppData\Local\Programs\Python\Python312\Lib\site-packages\django\contrib\auth\decorators.py", line 60, in _view_wrapper
    return view_func(request, *args, **kwargs)
           ^^^^^^^^^^^^^^^^^^^^^^^^^^^^^^^^^^^
  File "C:\Users\Mobile Gandom\Desktop\programming\coffee_shop_3_different\coffe_shop_page_o3\shop\views.py", line 996, in cart_count
    count = cart.get_total_quantity()
            ^^^^^^^^^^^^^^^^^^^^^^^^^
  File "C:\Users\Mobile Gandom\Desktop\programming\coffee_shop_3_different\coffe_shop_page_o3\shop\models.py", line 84, in get_total_quantity
    return sum(item.quantity for item in self.items.all())
                                         ^^^^^^^^^^^^^^^^
  File "C:\Users\Mobile Gandom\AppData\Local\Programs\Python\Python312\Lib\site-packages\django\db\models\query.py", line 400, in __iter__
    self._fetch_all()
  File "C:\Users\Mobile Gandom\AppData\Local\Programs\Python\Python312\Lib\site-packages\django\db\models\query.py", line 1928, in _fetch_all
    self._result_cache = list(self._iterable_class(self))
                         ^^^^^^^^^^^^^^^^^^^^^^^^^^^^^^^^
  File "C:\Users\Mobile Gandom\AppData\Local\Programs\Python\Python312\Lib\site-packages\django\db\models\query.py", line 91, in __iter__
    results = compiler.execute_sql(
              ^^^^^^^^^^^^^^^^^^^^^
  File "C:\Users\Mobile Gandom\AppData\Local\Programs\Python\Python312\Lib\site-packages\django\db\models\sql\compiler.py", line 1574, in execute_sql
    cursor.execute(sql, params)
  File "C:\Users\Mobile Gandom\AppData\Local\Programs\Python\Python312\Lib\site-packages\django\db\backends\utils.py", line 122, in execute
    return super().execute(sql, params)
           ^^^^^^^^^^^^^^^^^^^^^^^^^^^^
  File "C:\Users\Mobile Gandom\AppData\Local\Programs\Python\Python312\Lib\site-packages\django\db\backends\utils.py", line 79, in execute
    return self._execute_with_wrappers(
           ^^^^^^^^^^^^^^^^^^^^^^^^^^^^
  File "C:\Users\Mobile Gandom\AppData\Local\Programs\Python\Python312\Lib\site-packages\django\db\backends\utils.py", line 92, in _execute_with_wrappers
    return executor(sql, params, many, context)
           ^^^^^^^^^^^^^^^^^^^^^^^^^^^^^^^^^^^^
  File "C:\Users\Mobile Gandom\AppData\Local\Programs\Python\Python312\Lib\site-packages\django\db\backends\utils.py", line 100, in _execute
    with self.db.wrap_database_errors:
         ^^^^^^^^^^^^^^^^^^^^^^^^^^^^
  File "C:\Users\Mobile Gandom\AppData\Local\Programs\Python\Python312\Lib\site-packages\django\db\utils.py", line 91, in __exit__
    raise dj_exc_value.with_traceback(traceback) from exc_value
  File "C:\Users\Mobile Gandom\AppData\Local\Programs\Python\Python312\Lib\site-packages\django\db\backends\utils.py", line 105, in _execute
    return self.cursor.execute(sql, params)
           ^^^^^^^^^^^^^^^^^^^^^^^^^^^^^^^^
  File "C:\Users\Mobile Gandom\AppData\Local\Programs\Python\Python312\Lib\site-packages\django\db\backends\sqlite3\base.py", line 354, in execute
    return super().execute(query, params)
           ^^^^^^^^^^^^^^^^^^^^^^^^^^^^^^
django.db.utils.OperationalError: no such column: shop_cartitem.grind_type
INFO 2025-08-06 12:53:06,614 error_handling 13824 10364 Starting operation: product_detail
ERROR 2025-08-06 12:53:06,616 error_handling 13824 10364 Operation failed: product_detail after 0.00s
ERROR 2025-08-06 12:53:06,617 error_handling 13824 10364 Unexpected error in product_detail: no such column: shop_product.available_grinds
ERROR 2025-08-06 12:53:06,648 error_handling 13824 10364 Traceback (most recent call last):
  File "C:\Users\Mobile Gandom\AppData\Local\Programs\Python\Python312\Lib\site-packages\django\db\backends\utils.py", line 105, in _execute
    return self.cursor.execute(sql, params)
           ^^^^^^^^^^^^^^^^^^^^^^^^^^^^^^^^
  File "C:\Users\Mobile Gandom\AppData\Local\Programs\Python\Python312\Lib\site-packages\django\db\backends\sqlite3\base.py", line 354, in execute
    return super().execute(query, params)
           ^^^^^^^^^^^^^^^^^^^^^^^^^^^^^^
sqlite3.OperationalError: no such column: shop_product.available_grinds

The above exception was the direct cause of the following exception:

Traceback (most recent call last):
  File "C:\Users\Mobile Gandom\Desktop\programming\coffee_shop_3_different\coffe_shop_page_o3\shop\error_handling.py", line 112, in wrapper
    return func(request, *args, **kwargs)
           ^^^^^^^^^^^^^^^^^^^^^^^^^^^^^^
  File "C:\Users\Mobile Gandom\Desktop\programming\coffee_shop_3_different\coffe_shop_page_o3\shop\views.py", line 179, in product_detail
    product = get_object_or_404(
              ^^^^^^^^^^^^^^^^^^
  File "C:\Users\Mobile Gandom\AppData\Local\Programs\Python\Python312\Lib\site-packages\django\shortcuts.py", line 86, in get_object_or_404
    return queryset.get(*args, **kwargs)
           ^^^^^^^^^^^^^^^^^^^^^^^^^^^^^
  File "C:\Users\Mobile Gandom\AppData\Local\Programs\Python\Python312\Lib\site-packages\django\db\models\query.py", line 645, in get
    num = len(clone)
          ^^^^^^^^^^
  File "C:\Users\Mobile Gandom\AppData\Local\Programs\Python\Python312\Lib\site-packages\django\db\models\query.py", line 382, in __len__
    self._fetch_all()
  File "C:\Users\Mobile Gandom\AppData\Local\Programs\Python\Python312\Lib\site-packages\django\db\models\query.py", line 1928, in _fetch_all
    self._result_cache = list(self._iterable_class(self))
                         ^^^^^^^^^^^^^^^^^^^^^^^^^^^^^^^^
  File "C:\Users\Mobile Gandom\AppData\Local\Programs\Python\Python312\Lib\site-packages\django\db\models\query.py", line 91, in __iter__
    results = compiler.execute_sql(
              ^^^^^^^^^^^^^^^^^^^^^
  File "C:\Users\Mobile Gandom\AppData\Local\Programs\Python\Python312\Lib\site-packages\django\db\models\sql\compiler.py", line 1574, in execute_sql
    cursor.execute(sql, params)
  File "C:\Users\Mobile Gandom\AppData\Local\Programs\Python\Python312\Lib\site-packages\django\db\backends\utils.py", line 122, in execute
    return super().execute(sql, params)
           ^^^^^^^^^^^^^^^^^^^^^^^^^^^^
  File "C:\Users\Mobile Gandom\AppData\Local\Programs\Python\Python312\Lib\site-packages\django\db\backends\utils.py", line 79, in execute
    return self._execute_with_wrappers(
           ^^^^^^^^^^^^^^^^^^^^^^^^^^^^
  File "C:\Users\Mobile Gandom\AppData\Local\Programs\Python\Python312\Lib\site-packages\django\db\backends\utils.py", line 92, in _execute_with_wrappers
    return executor(sql, params, many, context)
           ^^^^^^^^^^^^^^^^^^^^^^^^^^^^^^^^^^^^
  File "C:\Users\Mobile Gandom\AppData\Local\Programs\Python\Python312\Lib\site-packages\django\db\backends\utils.py", line 100, in _execute
    with self.db.wrap_database_errors:
         ^^^^^^^^^^^^^^^^^^^^^^^^^^^^
  File "C:\Users\Mobile Gandom\AppData\Local\Programs\Python\Python312\Lib\site-packages\django\db\utils.py", line 91, in __exit__
    raise dj_exc_value.with_traceback(traceback) from exc_value
  File "C:\Users\Mobile Gandom\AppData\Local\Programs\Python\Python312\Lib\site-packages\django\db\backends\utils.py", line 105, in _execute
    return self.cursor.execute(sql, params)
           ^^^^^^^^^^^^^^^^^^^^^^^^^^^^^^^^
  File "C:\Users\Mobile Gandom\AppData\Local\Programs\Python\Python312\Lib\site-packages\django\db\backends\sqlite3\base.py", line 354, in execute
    return super().execute(query, params)
           ^^^^^^^^^^^^^^^^^^^^^^^^^^^^^^
django.db.utils.OperationalError: no such column: shop_product.available_grinds

ERROR 2025-08-06 12:53:06,653 error_handling 13824 10364 Error in product_detail after 0.04s: shop/error.html
ERROR 2025-08-06 12:53:06,709 log 13824 10364 Internal Server Error: /shop/product/4/
Traceback (most recent call last):
  File "C:\Users\Mobile Gandom\AppData\Local\Programs\Python\Python312\Lib\site-packages\django\db\backends\utils.py", line 105, in _execute
    return self.cursor.execute(sql, params)
           ^^^^^^^^^^^^^^^^^^^^^^^^^^^^^^^^
  File "C:\Users\Mobile Gandom\AppData\Local\Programs\Python\Python312\Lib\site-packages\django\db\backends\sqlite3\base.py", line 354, in execute
    return super().execute(query, params)
           ^^^^^^^^^^^^^^^^^^^^^^^^^^^^^^
sqlite3.OperationalError: no such column: shop_product.available_grinds

The above exception was the direct cause of the following exception:

Traceback (most recent call last):
  File "C:\Users\Mobile Gandom\Desktop\programming\coffee_shop_3_different\coffe_shop_page_o3\shop\error_handling.py", line 112, in wrapper
    return func(request, *args, **kwargs)
           ^^^^^^^^^^^^^^^^^^^^^^^^^^^^^^
  File "C:\Users\Mobile Gandom\Desktop\programming\coffee_shop_3_different\coffe_shop_page_o3\shop\views.py", line 179, in product_detail
    product = get_object_or_404(
              ^^^^^^^^^^^^^^^^^^
  File "C:\Users\Mobile Gandom\AppData\Local\Programs\Python\Python312\Lib\site-packages\django\shortcuts.py", line 86, in get_object_or_404
    return queryset.get(*args, **kwargs)
           ^^^^^^^^^^^^^^^^^^^^^^^^^^^^^
  File "C:\Users\Mobile Gandom\AppData\Local\Programs\Python\Python312\Lib\site-packages\django\db\models\query.py", line 645, in get
    num = len(clone)
          ^^^^^^^^^^
  File "C:\Users\Mobile Gandom\AppData\Local\Programs\Python\Python312\Lib\site-packages\django\db\models\query.py", line 382, in __len__
    self._fetch_all()
  File "C:\Users\Mobile Gandom\AppData\Local\Programs\Python\Python312\Lib\site-packages\django\db\models\query.py", line 1928, in _fetch_all
    self._result_cache = list(self._iterable_class(self))
                         ^^^^^^^^^^^^^^^^^^^^^^^^^^^^^^^^
  File "C:\Users\Mobile Gandom\AppData\Local\Programs\Python\Python312\Lib\site-packages\django\db\models\query.py", line 91, in __iter__
    results = compiler.execute_sql(
              ^^^^^^^^^^^^^^^^^^^^^
  File "C:\Users\Mobile Gandom\AppData\Local\Programs\Python\Python312\Lib\site-packages\django\db\models\sql\compiler.py", line 1574, in execute_sql
    cursor.execute(sql, params)
  File "C:\Users\Mobile Gandom\AppData\Local\Programs\Python\Python312\Lib\site-packages\django\db\backends\utils.py", line 122, in execute
    return super().execute(sql, params)
           ^^^^^^^^^^^^^^^^^^^^^^^^^^^^
  File "C:\Users\Mobile Gandom\AppData\Local\Programs\Python\Python312\Lib\site-packages\django\db\backends\utils.py", line 79, in execute
    return self._execute_with_wrappers(
           ^^^^^^^^^^^^^^^^^^^^^^^^^^^^
  File "C:\Users\Mobile Gandom\AppData\Local\Programs\Python\Python312\Lib\site-packages\django\db\backends\utils.py", line 92, in _execute_with_wrappers
    return executor(sql, params, many, context)
           ^^^^^^^^^^^^^^^^^^^^^^^^^^^^^^^^^^^^
  File "C:\Users\Mobile Gandom\AppData\Local\Programs\Python\Python312\Lib\site-packages\django\db\backends\utils.py", line 100, in _execute
    with self.db.wrap_database_errors:
         ^^^^^^^^^^^^^^^^^^^^^^^^^^^^
  File "C:\Users\Mobile Gandom\AppData\Local\Programs\Python\Python312\Lib\site-packages\django\db\utils.py", line 91, in __exit__
    raise dj_exc_value.with_traceback(traceback) from exc_value
  File "C:\Users\Mobile Gandom\AppData\Local\Programs\Python\Python312\Lib\site-packages\django\db\backends\utils.py", line 105, in _execute
    return self.cursor.execute(sql, params)
           ^^^^^^^^^^^^^^^^^^^^^^^^^^^^^^^^
  File "C:\Users\Mobile Gandom\AppData\Local\Programs\Python\Python312\Lib\site-packages\django\db\backends\sqlite3\base.py", line 354, in execute
    return super().execute(query, params)
           ^^^^^^^^^^^^^^^^^^^^^^^^^^^^^^
django.db.utils.OperationalError: no such column: shop_product.available_grinds

During handling of the above exception, another exception occurred:

Traceback (most recent call last):
  File "C:\Users\Mobile Gandom\AppData\Local\Programs\Python\Python312\Lib\site-packages\django\core\handlers\exception.py", line 55, in inner
    response = get_response(request)
               ^^^^^^^^^^^^^^^^^^^^^
  File "C:\Users\Mobile Gandom\AppData\Local\Programs\Python\Python312\Lib\site-packages\django\core\handlers\base.py", line 197, in _get_response
    response = wrapped_callback(request, *callback_args, **callback_kwargs)
               ^^^^^^^^^^^^^^^^^^^^^^^^^^^^^^^^^^^^^^^^^^^^^^^^^^^^^^^^^^^^
  File "C:\Users\Mobile Gandom\Desktop\programming\coffee_shop_3_different\coffe_shop_page_o3\shop\error_handling.py", line 22, in wrapper
    result = func(*args, **kwargs)
             ^^^^^^^^^^^^^^^^^^^^^
  File "C:\Users\Mobile Gandom\Desktop\programming\coffee_shop_3_different\coffe_shop_page_o3\shop\error_handling.py", line 128, in wrapper
    return render(request, 'shop/error.html', {
           ^^^^^^^^^^^^^^^^^^^^^^^^^^^^^^^^^^^^
  File "C:\Users\Mobile Gandom\AppData\Local\Programs\Python\Python312\Lib\site-packages\django\shortcuts.py", line 25, in render
    content = loader.render_to_string(template_name, context, request, using=using)
              ^^^^^^^^^^^^^^^^^^^^^^^^^^^^^^^^^^^^^^^^^^^^^^^^^^^^^^^^^^^^^^^^^^^^^
  File "C:\Users\Mobile Gandom\AppData\Local\Programs\Python\Python312\Lib\site-packages\django\template\loader.py", line 61, in render_to_string
    template = get_template(template_name, using=using)
               ^^^^^^^^^^^^^^^^^^^^^^^^^^^^^^^^^^^^^^^^
  File "C:\Users\Mobile Gandom\AppData\Local\Programs\Python\Python312\Lib\site-packages\django\template\loader.py", line 19, in get_template
    raise TemplateDoesNotExist(template_name, chain=chain)
django.template.exceptions.TemplateDoesNotExist: shop/error.html
