INFO 2025-08-03 04:39:04,944 autoreload 9112 7680 Watching for file changes with StatReloader
INFO 2025-08-03 04:39:40,686 autoreload 8796 1732 Watching for file changes with StatReloader
WARNING 2025-08-03 04:39:46,596 log 8796 1888 Not Found: /accounts/login/
ERROR 2025-08-03 04:41:11,387 log 8796 1888 Internal Server Error: /shop/profile/
Traceback (most recent call last):
  File "C:\Users\Mobile Gandom\AppData\Local\Programs\Python\Python312\Lib\site-packages\django\core\handlers\exception.py", line 55, in inner
    response = get_response(request)
               ^^^^^^^^^^^^^^^^^^^^^
  File "C:\Users\Mobile Gandom\AppData\Local\Programs\Python\Python312\Lib\site-packages\django\core\handlers\base.py", line 197, in _get_response
    response = wrapped_callback(request, *callback_args, **callback_kwargs)
               ^^^^^^^^^^^^^^^^^^^^^^^^^^^^^^^^^^^^^^^^^^^^^^^^^^^^^^^^^^^^
  File "C:\Users\Mobile Gandom\AppData\Local\Programs\Python\Python312\Lib\site-packages\django\contrib\auth\decorators.py", line 60, in _view_wrapper
    return view_func(request, *args, **kwargs)
           ^^^^^^^^^^^^^^^^^^^^^^^^^^^^^^^^^^^
  File "C:\Users\Mobile Gandom\Desktop\programming\coffe_shop_page_Revision1\shop\views.py", line 993, in profile
    return render(request, 'shop/profile.html', context)
           ^^^^^^^^^^^^^^^^^^^^^^^^^^^^^^^^^^^^^^^^^^^^^
  File "C:\Users\Mobile Gandom\AppData\Local\Programs\Python\Python312\Lib\site-packages\django\shortcuts.py", line 25, in render
    content = loader.render_to_string(template_name, context, request, using=using)
              ^^^^^^^^^^^^^^^^^^^^^^^^^^^^^^^^^^^^^^^^^^^^^^^^^^^^^^^^^^^^^^^^^^^^^
  File "C:\Users\Mobile Gandom\AppData\Local\Programs\Python\Python312\Lib\site-packages\django\template\loader.py", line 61, in render_to_string
    template = get_template(template_name, using=using)
               ^^^^^^^^^^^^^^^^^^^^^^^^^^^^^^^^^^^^^^^^
  File "C:\Users\Mobile Gandom\AppData\Local\Programs\Python\Python312\Lib\site-packages\django\template\loader.py", line 19, in get_template
    raise TemplateDoesNotExist(template_name, chain=chain)
django.template.exceptions.TemplateDoesNotExist: shop/profile.html
INFO 2025-08-03 04:42:28,182 autoreload 8796 1732 C:\Users\Mobile Gandom\Desktop\programming\coffe_shop_page_Revision1\shop\views.py changed, reloading.
INFO 2025-08-03 04:42:28,816 autoreload 7788 1744 Watching for file changes with StatReloader
INFO 2025-08-03 04:45:57,164 autoreload 3212 3168 Watching for file changes with StatReloader
ERROR 2025-08-03 06:08:02,146 log 3212 7272 Internal Server Error: /shop/profile/
Traceback (most recent call last):
  File "C:\Users\Mobile Gandom\AppData\Local\Programs\Python\Python312\Lib\site-packages\django\core\handlers\exception.py", line 55, in inner
    response = get_response(request)
               ^^^^^^^^^^^^^^^^^^^^^
  File "C:\Users\Mobile Gandom\AppData\Local\Programs\Python\Python312\Lib\site-packages\django\core\handlers\base.py", line 197, in _get_response
    response = wrapped_callback(request, *callback_args, **callback_kwargs)
               ^^^^^^^^^^^^^^^^^^^^^^^^^^^^^^^^^^^^^^^^^^^^^^^^^^^^^^^^^^^^
  File "C:\Users\Mobile Gandom\AppData\Local\Programs\Python\Python312\Lib\site-packages\django\contrib\auth\decorators.py", line 60, in _view_wrapper
    return view_func(request, *args, **kwargs)
           ^^^^^^^^^^^^^^^^^^^^^^^^^^^^^^^^^^^
  File "C:\Users\Mobile Gandom\Desktop\programming\coffe_shop_page_Revision1\shop\views.py", line 974, in profile
    user_profile = request.user.profile
                   ^^^^^^^^^^^^^^^^^^^^
  File "C:\Users\Mobile Gandom\AppData\Local\Programs\Python\Python312\Lib\site-packages\django\utils\functional.py", line 253, in inner
    return func(_wrapped, *args)
           ^^^^^^^^^^^^^^^^^^^^^
  File "C:\Users\Mobile Gandom\AppData\Local\Programs\Python\Python312\Lib\site-packages\django\db\models\fields\related_descriptors.py", line 531, in __get__
    raise self.RelatedObjectDoesNotExist(
django.contrib.auth.models.User.profile.RelatedObjectDoesNotExist: User has no profile.
ERROR 2025-08-03 06:08:13,388 log 3212 7272 Internal Server Error: /shop/profile/
Traceback (most recent call last):
  File "C:\Users\Mobile Gandom\AppData\Local\Programs\Python\Python312\Lib\site-packages\django\core\handlers\exception.py", line 55, in inner
    response = get_response(request)
               ^^^^^^^^^^^^^^^^^^^^^
  File "C:\Users\Mobile Gandom\AppData\Local\Programs\Python\Python312\Lib\site-packages\django\core\handlers\base.py", line 197, in _get_response
    response = wrapped_callback(request, *callback_args, **callback_kwargs)
               ^^^^^^^^^^^^^^^^^^^^^^^^^^^^^^^^^^^^^^^^^^^^^^^^^^^^^^^^^^^^
  File "C:\Users\Mobile Gandom\AppData\Local\Programs\Python\Python312\Lib\site-packages\django\contrib\auth\decorators.py", line 60, in _view_wrapper
    return view_func(request, *args, **kwargs)
           ^^^^^^^^^^^^^^^^^^^^^^^^^^^^^^^^^^^
  File "C:\Users\Mobile Gandom\Desktop\programming\coffe_shop_page_Revision1\shop\views.py", line 974, in profile
    user_profile = request.user.profile
                   ^^^^^^^^^^^^^^^^^^^^
  File "C:\Users\Mobile Gandom\AppData\Local\Programs\Python\Python312\Lib\site-packages\django\utils\functional.py", line 253, in inner
    return func(_wrapped, *args)
           ^^^^^^^^^^^^^^^^^^^^^
  File "C:\Users\Mobile Gandom\AppData\Local\Programs\Python\Python312\Lib\site-packages\django\db\models\fields\related_descriptors.py", line 531, in __get__
    raise self.RelatedObjectDoesNotExist(
django.contrib.auth.models.User.profile.RelatedObjectDoesNotExist: User has no profile.
ERROR 2025-08-03 06:58:12,685 log 3212 6744 Internal Server Error: /shop/profile/
Traceback (most recent call last):
  File "C:\Users\Mobile Gandom\AppData\Local\Programs\Python\Python312\Lib\site-packages\django\core\handlers\exception.py", line 55, in inner
    response = get_response(request)
               ^^^^^^^^^^^^^^^^^^^^^
  File "C:\Users\Mobile Gandom\AppData\Local\Programs\Python\Python312\Lib\site-packages\django\core\handlers\base.py", line 197, in _get_response
    response = wrapped_callback(request, *callback_args, **callback_kwargs)
               ^^^^^^^^^^^^^^^^^^^^^^^^^^^^^^^^^^^^^^^^^^^^^^^^^^^^^^^^^^^^
  File "C:\Users\Mobile Gandom\AppData\Local\Programs\Python\Python312\Lib\site-packages\django\contrib\auth\decorators.py", line 60, in _view_wrapper
    return view_func(request, *args, **kwargs)
           ^^^^^^^^^^^^^^^^^^^^^^^^^^^^^^^^^^^
  File "C:\Users\Mobile Gandom\Desktop\programming\coffe_shop_page_Revision1\shop\views.py", line 974, in profile
    user_profile = request.user.profile
                   ^^^^^^^^^^^^^^^^^^^^
  File "C:\Users\Mobile Gandom\AppData\Local\Programs\Python\Python312\Lib\site-packages\django\utils\functional.py", line 253, in inner
    return func(_wrapped, *args)
           ^^^^^^^^^^^^^^^^^^^^^
  File "C:\Users\Mobile Gandom\AppData\Local\Programs\Python\Python312\Lib\site-packages\django\db\models\fields\related_descriptors.py", line 531, in __get__
    raise self.RelatedObjectDoesNotExist(
django.contrib.auth.models.User.profile.RelatedObjectDoesNotExist: User has no profile.
INFO 2025-08-03 07:11:07,578 autoreload 9316 10048 Watching for file changes with StatReloader
ERROR 2025-08-03 07:12:12,905 recursion_prevention 9316 6400 Request chain timeout. Current path: /shop/cart/count/
ERROR 2025-08-03 07:12:12,906 log 9316 6400 Internal Server Error: /shop/cart/count/
ERROR 2025-08-03 07:14:42,905 recursion_prevention 9316 9416 Request chain timeout. Current path: /shop/cart/count/
ERROR 2025-08-03 07:14:42,907 log 9316 9416 Internal Server Error: /shop/cart/count/
ERROR 2025-08-03 07:15:45,896 recursion_prevention 9316 5968 Request chain timeout. Current path: /shop/cart/count/
ERROR 2025-08-03 07:15:45,897 log 9316 5968 Internal Server Error: /shop/cart/count/
ERROR 2025-08-03 07:17:45,898 recursion_prevention 9316 1572 Request chain timeout. Current path: /shop/cart/count/
ERROR 2025-08-03 07:17:45,898 log 9316 1572 Internal Server Error: /shop/cart/count/
ERROR 2025-08-03 07:19:45,890 recursion_prevention 9316 11328 Request chain timeout. Current path: /shop/cart/count/
ERROR 2025-08-03 07:19:45,891 log 9316 11328 Internal Server Error: /shop/cart/count/
ERROR 2025-08-03 07:21:45,894 recursion_prevention 9316 8408 Request chain timeout. Current path: /shop/cart/count/
ERROR 2025-08-03 07:21:45,895 log 9316 8408 Internal Server Error: /shop/cart/count/
ERROR 2025-08-03 07:23:45,899 recursion_prevention 9316 4216 Request chain timeout. Current path: /shop/cart/count/
ERROR 2025-08-03 07:23:45,900 log 9316 4216 Internal Server Error: /shop/cart/count/
INFO 2025-08-03 07:25:21,459 autoreload 5756 2696 Watching for file changes with StatReloader
ERROR 2025-08-03 07:26:34,896 recursion_prevention 5756 12660 Request chain timeout. Current path: /shop/cart/count/
ERROR 2025-08-03 07:26:34,898 log 5756 12660 Internal Server Error: /shop/cart/count/
INFO 2025-08-03 09:01:36,505 autoreload 9276 1528 Watching for file changes with StatReloader
INFO 2025-08-03 09:02:43,716 autoreload 11424 10304 Watching for file changes with StatReloader
ERROR 2025-08-03 09:04:33,890 recursion_prevention 11424 13024 Request chain timeout. Current path: /shop/cart/count/
ERROR 2025-08-03 09:04:33,891 log 11424 13024 Internal Server Error: /shop/cart/count/
ERROR 2025-08-03 09:06:01,358 log 11424 10264 Internal Server Error: /shop/search/
Traceback (most recent call last):
  File "C:\Users\Mobile Gandom\AppData\Local\Programs\Python\Python312\Lib\site-packages\django\core\handlers\exception.py", line 55, in inner
    response = get_response(request)
               ^^^^^^^^^^^^^^^^^^^^^
  File "C:\Users\Mobile Gandom\AppData\Local\Programs\Python\Python312\Lib\site-packages\django\core\handlers\base.py", line 197, in _get_response
    response = wrapped_callback(request, *callback_args, **callback_kwargs)
               ^^^^^^^^^^^^^^^^^^^^^^^^^^^^^^^^^^^^^^^^^^^^^^^^^^^^^^^^^^^^
  File "C:\Users\Mobile Gandom\Desktop\programming\coffe_shop_page_Revision1\shop\views.py", line 1252, in search_products
    products = Product.objects.filter(is_active=True)
               ^^^^^^^^^^^^^^^^^^^^^^^^^^^^^^^^^^^^^^
  File "C:\Users\Mobile Gandom\AppData\Local\Programs\Python\Python312\Lib\site-packages\django\db\models\manager.py", line 87, in manager_method
    return getattr(self.get_queryset(), name)(*args, **kwargs)
           ^^^^^^^^^^^^^^^^^^^^^^^^^^^^^^^^^^^^^^^^^^^^^^^^^^^
  File "C:\Users\Mobile Gandom\AppData\Local\Programs\Python\Python312\Lib\site-packages\django\db\models\query.py", line 1476, in filter
    return self._filter_or_exclude(False, args, kwargs)
           ^^^^^^^^^^^^^^^^^^^^^^^^^^^^^^^^^^^^^^^^^^^^
  File "C:\Users\Mobile Gandom\AppData\Local\Programs\Python\Python312\Lib\site-packages\django\db\models\query.py", line 1494, in _filter_or_exclude
    clone._filter_or_exclude_inplace(negate, args, kwargs)
  File "C:\Users\Mobile Gandom\AppData\Local\Programs\Python\Python312\Lib\site-packages\django\db\models\query.py", line 1501, in _filter_or_exclude_inplace
    self._query.add_q(Q(*args, **kwargs))
  File "C:\Users\Mobile Gandom\AppData\Local\Programs\Python\Python312\Lib\site-packages\django\db\models\sql\query.py", line 1609, in add_q
    clause, _ = self._add_q(q_object, self.used_aliases)
                ^^^^^^^^^^^^^^^^^^^^^^^^^^^^^^^^^^^^^^^^
  File "C:\Users\Mobile Gandom\AppData\Local\Programs\Python\Python312\Lib\site-packages\django\db\models\sql\query.py", line 1641, in _add_q
    child_clause, needed_inner = self.build_filter(
                                 ^^^^^^^^^^^^^^^^^^
  File "C:\Users\Mobile Gandom\AppData\Local\Programs\Python\Python312\Lib\site-packages\django\db\models\sql\query.py", line 1491, in build_filter
    lookups, parts, reffed_expression = self.solve_lookup_type(arg, summarize)
                                        ^^^^^^^^^^^^^^^^^^^^^^^^^^^^^^^^^^^^^^
  File "C:\Users\Mobile Gandom\AppData\Local\Programs\Python\Python312\Lib\site-packages\django\db\models\sql\query.py", line 1303, in solve_lookup_type
    _, field, _, lookup_parts = self.names_to_path(lookup_splitted, self.get_meta())
                                ^^^^^^^^^^^^^^^^^^^^^^^^^^^^^^^^^^^^^^^^^^^^^^^^^^^^
  File "C:\Users\Mobile Gandom\AppData\Local\Programs\Python\Python312\Lib\site-packages\django\db\models\sql\query.py", line 1768, in names_to_path
    raise FieldError(
django.core.exceptions.FieldError: Cannot resolve keyword 'is_active' into field. Choices are: cartitem, category, category_id, comments, created_at, description, favorites, featured, id, image, interactions, likes, name, orderitem, price, productrecommendation, searchquery, stock, updated_at, useractivity
ERROR 2025-08-03 09:06:46,012 views 11424 10264 Error in customer insights: Cannot resolve keyword 'orders' into field. Choices are: activities, addresses, cart, comment, date_joined, email, first_name, groups, id, is_active, is_staff, is_superuser, last_login, last_name, logentry, loyalty, notifications, order, password, product_interactions, productfavorite, productlike, profile, recommendations, searchquery, segment, user_permissions, username
WARNING 2025-08-03 09:06:58,668 log 11424 10264 Not Found: /shop/costumer_insights
WARNING 2025-08-03 09:07:02,287 log 11424 10264 Not Found: /shop/costumer_insight
WARNING 2025-08-03 09:07:12,154 log 11424 10264 Not Found: /shop/custumer_insight
WARNING 2025-08-03 09:07:15,615 log 11424 10264 Not Found: /shop/customer_insight
WARNING 2025-08-03 09:07:17,751 log 11424 10264 Not Found: /shop/customer_insights
ERROR 2025-08-03 09:07:33,502 views 11424 10264 Error in customer insights: Cannot resolve keyword 'orders' into field. Choices are: activities, addresses, cart, comment, date_joined, email, first_name, groups, id, is_active, is_staff, is_superuser, last_login, last_name, logentry, loyalty, notifications, order, password, product_interactions, productfavorite, productlike, profile, recommendations, searchquery, segment, user_permissions, username
INFO 2025-08-03 09:08:12,884 error_handling 11424 10264 Starting operation: system_status
ERROR 2025-08-03 09:08:12,959 error_handling 11424 10264 Operation failed: system_status after 0.07s
ERROR 2025-08-03 09:08:12,959 error_handling 11424 10264 Unexpected error in system_status: name 'check_database_health' is not defined
ERROR 2025-08-03 09:08:12,965 error_handling 11424 10264 Traceback (most recent call last):
  File "C:\Users\Mobile Gandom\Desktop\programming\coffe_shop_page_Revision1\shop\error_handling.py", line 112, in wrapper
    return func(request, *args, **kwargs)
           ^^^^^^^^^^^^^^^^^^^^^^^^^^^^^^
  File "C:\Users\Mobile Gandom\Desktop\programming\coffe_shop_page_Revision1\shop\views.py", line 1390, in system_status
    'database': check_database_health(),
                ^^^^^^^^^^^^^^^^^^^^^
NameError: name 'check_database_health' is not defined

ERROR 2025-08-03 09:08:12,967 error_handling 11424 10264 Error in system_status after 0.08s: shop/error.html
ERROR 2025-08-03 09:08:12,987 log 11424 10264 Internal Server Error: /shop/system-status/
Traceback (most recent call last):
  File "C:\Users\Mobile Gandom\Desktop\programming\coffe_shop_page_Revision1\shop\error_handling.py", line 112, in wrapper
    return func(request, *args, **kwargs)
           ^^^^^^^^^^^^^^^^^^^^^^^^^^^^^^
  File "C:\Users\Mobile Gandom\Desktop\programming\coffe_shop_page_Revision1\shop\views.py", line 1390, in system_status
    'database': check_database_health(),
                ^^^^^^^^^^^^^^^^^^^^^
NameError: name 'check_database_health' is not defined

During handling of the above exception, another exception occurred:

Traceback (most recent call last):
  File "C:\Users\Mobile Gandom\AppData\Local\Programs\Python\Python312\Lib\site-packages\django\core\handlers\exception.py", line 55, in inner
    response = get_response(request)
               ^^^^^^^^^^^^^^^^^^^^^
  File "C:\Users\Mobile Gandom\AppData\Local\Programs\Python\Python312\Lib\site-packages\django\core\handlers\base.py", line 197, in _get_response
    response = wrapped_callback(request, *callback_args, **callback_kwargs)
               ^^^^^^^^^^^^^^^^^^^^^^^^^^^^^^^^^^^^^^^^^^^^^^^^^^^^^^^^^^^^
  File "C:\Users\Mobile Gandom\Desktop\programming\coffe_shop_page_Revision1\shop\error_handling.py", line 22, in wrapper
    result = func(*args, **kwargs)
             ^^^^^^^^^^^^^^^^^^^^^
  File "C:\Users\Mobile Gandom\Desktop\programming\coffe_shop_page_Revision1\shop\error_handling.py", line 128, in wrapper
    return render(request, 'shop/error.html', {
           ^^^^^^^^^^^^^^^^^^^^^^^^^^^^^^^^^^^^
  File "C:\Users\Mobile Gandom\AppData\Local\Programs\Python\Python312\Lib\site-packages\django\shortcuts.py", line 25, in render
    content = loader.render_to_string(template_name, context, request, using=using)
              ^^^^^^^^^^^^^^^^^^^^^^^^^^^^^^^^^^^^^^^^^^^^^^^^^^^^^^^^^^^^^^^^^^^^^
  File "C:\Users\Mobile Gandom\AppData\Local\Programs\Python\Python312\Lib\site-packages\django\template\loader.py", line 61, in render_to_string
    template = get_template(template_name, using=using)
               ^^^^^^^^^^^^^^^^^^^^^^^^^^^^^^^^^^^^^^^^
  File "C:\Users\Mobile Gandom\AppData\Local\Programs\Python\Python312\Lib\site-packages\django\template\loader.py", line 19, in get_template
    raise TemplateDoesNotExist(template_name, chain=chain)
django.template.exceptions.TemplateDoesNotExist: shop/error.html
INFO 2025-08-03 09:08:36,446 autoreload 5868 11452 Watching for file changes with StatReloader
ERROR 2025-08-03 09:09:20,091 recursion_prevention 5868 9548 Request chain timeout. Current path: /shop/cart/count/
ERROR 2025-08-03 09:09:20,092 log 5868 9548 Internal Server Error: /shop/cart/count/
ERROR 2025-08-03 09:09:54,901 recursion_prevention 5868 8596 Request chain timeout. Current path: /shop/cart/count/
ERROR 2025-08-03 09:09:54,902 log 5868 8596 Internal Server Error: /shop/cart/count/
ERROR 2025-08-03 09:10:54,913 recursion_prevention 5868 5444 Request chain timeout. Current path: /shop/cart/count/
ERROR 2025-08-03 09:10:54,913 log 5868 5444 Internal Server Error: /shop/cart/count/
ERROR 2025-08-03 09:12:24,899 recursion_prevention 5868 12912 Request chain timeout. Current path: /shop/cart/count/
ERROR 2025-08-03 09:12:24,900 log 5868 12912 Internal Server Error: /shop/cart/count/
ERROR 2025-08-03 09:13:45,889 recursion_prevention 5868 9628 Request chain timeout. Current path: /shop/cart/count/
ERROR 2025-08-03 09:13:45,890 log 5868 9628 Internal Server Error: /shop/cart/count/
ERROR 2025-08-03 09:15:45,898 recursion_prevention 5868 10896 Request chain timeout. Current path: /shop/cart/count/
ERROR 2025-08-03 09:15:45,899 log 5868 10896 Internal Server Error: /shop/cart/count/
ERROR 2025-08-03 09:17:24,901 recursion_prevention 5868 2616 Request chain timeout. Current path: /shop/cart/count/
ERROR 2025-08-03 09:17:24,902 log 5868 2616 Internal Server Error: /shop/cart/count/
ERROR 2025-08-03 09:19:26,892 recursion_prevention 5868 11936 Request chain timeout. Current path: /shop/cart/count/
ERROR 2025-08-03 09:19:26,893 log 5868 11936 Internal Server Error: /shop/cart/count/
ERROR 2025-08-03 09:21:28,895 recursion_prevention 5868 1444 Request chain timeout. Current path: /shop/cart/count/
ERROR 2025-08-03 09:21:28,896 log 5868 1444 Internal Server Error: /shop/cart/count/
ERROR 2025-08-03 09:23:30,902 recursion_prevention 5868 5396 Request chain timeout. Current path: /shop/cart/count/
ERROR 2025-08-03 09:23:30,903 log 5868 5396 Internal Server Error: /shop/cart/count/
ERROR 2025-08-03 09:25:32,892 recursion_prevention 5868 12716 Request chain timeout. Current path: /shop/cart/count/
ERROR 2025-08-03 09:25:32,892 log 5868 12716 Internal Server Error: /shop/cart/count/
ERROR 2025-08-03 09:27:34,896 recursion_prevention 5868 8896 Request chain timeout. Current path: /shop/cart/count/
ERROR 2025-08-03 09:27:34,897 log 5868 8896 Internal Server Error: /shop/cart/count/
ERROR 2025-08-03 09:30:37,894 recursion_prevention 5868 3352 Request chain timeout. Current path: /shop/cart/count/
ERROR 2025-08-03 09:30:37,894 log 5868 3352 Internal Server Error: /shop/cart/count/
ERROR 2025-08-03 09:32:39,897 recursion_prevention 5868 6068 Request chain timeout. Current path: /shop/cart/count/
ERROR 2025-08-03 09:32:39,897 log 5868 6068 Internal Server Error: /shop/cart/count/
ERROR 2025-08-03 09:34:41,898 recursion_prevention 5868 12404 Request chain timeout. Current path: /shop/cart/count/
ERROR 2025-08-03 09:34:41,899 log 5868 12404 Internal Server Error: /shop/cart/count/
